Workbook

Sheet Main
B2: * all numbers in thousands, GBP
J3: Price | K3: 9.27 | L3: 927.00 GBX
B4: RENEW HOLDINGS PLC | J4: Shares | K4: 79138
B5: Company number: 650447 | J5: MC | K5: =K3*K4 -> 733609.26
B6: LON: RNWH | J6: Cash | K6: 80219
J7: Debt | K7: =15605+52000+8975 -> 76580
B8: Company: Engineering firm specializing in UK (and rest Europe) infrastructure maintenance | J8: EV | K8: =K5+K7-K6 -> 729970.26 | L8: *Strong net cash position
B9: Industry: Industrials
B10: Sector: Construction and Materials | J10: EBIT | K10: 61171 | L10: Y2024
J11: Earnings | K11: 41571 | L11: Y2024
B12: IPO: 2006
B13: Employees: 4,429 | J13: EV/EBIT | K13: =K8/K10 -> 11.933273
J14: EV/E | K14: =K8/K11 -> 17.559603
B15: Low risk business model | J15: P/E | K15: =K5/K11 -> 17.64714
B16: Markets with committed regulatory funding
B17: £600bn UK Government commitment to infrastructure | J17: Cash = cash and equivalents
B18: Delivering mission-critical infrastructure services across the UK | J18: Debt = borrowings + current/non-current lease liabilities (interest-bearing debt)
B21: Core Markets
B22: Rail | J22: Total assets | K22: =Model!H49 -> 547713 | L22: Y2024
B23: Infrastructure | C23: providing asset maintenance to the rail network | J23: Total liabilities | K23: =Model!H57 -> 341323 | L23: Y2024
B24: Energy | C24: specialist drainage, lighting and electricals at National Highways
B25: Environmental | C25: risk reduction operations at nuclear facilities | J25: Net Tangible Assets | K25: =K22-Model!H41-K23 -> 11293 | L25: =Assets - Intangible assets - Liabilities
C26: asset maintenance and renewals across water infrastructure | J26: NTABPS | K26: =K25/K4 -> 0.14270009 | L26: =NTA / SO
J27: NTABPS/P, % | K27: =K26/K3 -> 0.015393753 | L27: = % of share price backed by tangible net-assets
B28: Risks
B29: Dependency on government contracts & commitments | J29: Book Value | K29: =K22-K23 -> 206390
B30: Operating in complex, challenging and highly regulated environments | J30: BVPS | K30: =K29/K4 -> 2.6079759
B31: (Small tangible net-assets position as for industrial company) | J31: BVPS/P, % | K31: =K30/K3 -> 0.28133505
J32: Price-to-Book (P/B) | K32: =K5/K29 -> 3.5544806 | L32: *great book value ratio
B34: CEO | C34: Paul Scott
B35: CFO | C35: Sean Wyndham-Quin
B36: Chairman | C36: David Brown

Sheet Model
A1: Main
C2: Y2019 | D2: Y2020 | E2: Y2021 | F2: Y2022 | G2: Y2023 | H2: Y2024 | I2: Y2025 | J2: Y2026 | K2: Y2027 | L2: Y2028 | M2: Y2029 | N2: Y2030
B3: Revenue | C3: 599922 | D3: 620375 | E3: 775639 | F3: 816276 | G3: 848179 | H3: 1008970 | I3: =H3*1.05 -> 1059418.5 | J3: =I3*1.05 -> 1112389.4 | K3: =J3*1.05 -> 1168008.9 | L3: =K3*1.05 -> 1226409.3 | M3: =L3*1.05 -> 1287729.8 | N3: =M3*1.05 -> 1352116.3
B4: Cost of revenue | C4: 514299 | D4: 527274 | E4: 666454 | F4: 693336 | G4: 719534 | H4: 867306
B5: Gross profit | C5: =C3-C4 -> 85623 | D5: =D3-D4 -> 93101 | E5: =E3-E4 -> 109185 | F5: =F3-F4 -> 122940 | G5: =G3-G4 -> 128645 | H5: =H3-H4 -> 141664
B7: Administrative | C7: 58178 | D7: 60194 | E7: 68055 | F7: 76711 | G7: 74649 | H7: 84459
B8: Other income | C8: 0 | D8: 0 | E8: 0 | F8: 3655 | G8: 3865 | H8: 4165
B9: Joint ventures post-tax (loss) | C9: -96 | D9: 39 | E9: -11 | F9: -95 | G9: 154 | H9: 199
B10: Operating profit | C10: =C5-C7-C9+C8 -> 27541 | D10: =D5-D7-D9+D8 -> 32868 | E10: =E5-E7-E9+E8 -> 41141 | F10: =F5-F7-F9+F8 -> 49979 | G10: =G5-G7-G9+G8 -> 57707 | H10: =H5-H7-H9+H8 -> 61171 | I10: =I3*(1+$N$26) -> 1112389.4 | J10: =J3*(1+$N$26) -> 1168008.9 | K10: =K3*(1+$N$26) -> 1226409.3 | L10: =L3*(1+$N$26) -> 1287729.8 | M10: =M3*(1+$N$26) -> 1352116.3 | N10: =N3*(1+$N$26) -> 1419722.1
B12: Finance income | C12: 50 | D12: 44 | E12: 19 | F12: 16 | G12: 360 | H12: 791
B13: Finance costs | C13: 1244 | D13: 1343 | E13: 836 | F13: 573 | G13: 1285 | H13: 1828
B14: Other finance income | C14: 615 | D14: 532 | E14: 428 | F14: 33 | G14: 66 | H14: 90
B15: Pretax profit | C15: =C10+C12-C13+C14 -> 26962 | D15: =D10+D12-D13+D14 -> 32101 | E15: =E10+E12-E13+E14 -> 40752 | F15: =F10+F12-F13+F14 -> 49455 | G15: =G10+G12-G13+G14 -> 56848 | H15: =H10+H12-H13+H14 -> 60224
B17: Taxes | C17: 4705 | D17: 5759 | E17: 8669 | F17: 9548 | G17: 10742 | H17: 16213
B18: Profit continued activities | C18: =C15-C17 -> 22257 | D18: =D15-D17 -> 26342 | E18: =E15-E17 -> 32083 | F18: =F15-F17 -> 39907 | G18: =G15-G17 -> 46106 | H18: =H15-H17 -> 44011
B19: Loss from discontinued operations | C19: 0 | D19: 5590 | E19: 1620 | F19: 2242 | G19: 2722 | H19: 2440
B20: Profit (net income) | C20: =C18-C19 -> 22257 | D20: =D18-D19 -> 20752 | E20: =E18-E19 -> 30463 | F20: =F18-F19 -> 37665 | G20: =G18-G19 -> 43384 | H20: =H18-H19 -> 41571 | I20: =I3*0.03 -> 31782.555 | J20: =J3*0.03 -> 33371.683 | K20: =K3*0.03 -> 35040.267 | L20: =L3*0.03 -> 36792.28 | M20: =M3*0.03 -> 38631.894 | N20: =N3*0.03 -> 40563.489
B22: OCF | C22: 23441 | D22: 51854 | E22: =39167 -> 39167 | F22: =57163 -> 57163 | G22: 53777 | H22: =44435 -> 44435
B23: CapEx (PP&E) | C23: =2619 -> 2619 | D23: 3756 | E23: =4042 -> 4042 | F23: =5056 -> 5056 | G23: 5414 | H23: 6146
B24: FCF | C24: =C22-C23 -> 20822 | D24: =D22-D23 -> 48098 | E24: =E22-E23 -> 35125 | F24: =F22-F23 -> 52107 | G24: =G22-G23 -> 48363 | H24: =H22-H23 -> 38289 | I24: =I20*1.13 -> 35914.287 | J24: =J20*1.13 -> 37710.002 | K24: =K20*1.13 -> 39595.502 | L24: =L20*1.13 -> 41575.277 | M24: =M20*1.13 -> 43654.04 | N24: =N20*1.13 -> 45836.743 | O24: =N24*(1+$N$27) -> 46753.477 | P24: =O24*(1+$N$27) -> 47688.547 | Q24: =P24*(1+$N$27) -> 48642.318 | R24: =Q24*(1+$N$27) -> 49615.164 | S24: =R24*(1+$N$27) -> 50607.467 | T24: =S24*(1+$N$27) -> 51619.617 | U24: =T24*(1+$N$27) -> 52652.009 | V24: =U24*(1+$N$27) -> 53705.049 | ... JC24: =JB24*(1+$N$27) -> 6348286.4
J26: Median margins | K26: Average margins | M26: 5y revenue growth | N26: 0.05 | O26: Terminal | P26: =(N24*(1+N27))/N28-N27 -> 642167.77
B27: Gross margin | C27: =C5/C3 -> 0.14272355 | D27: =D5/D3 -> 0.15007213 | E27: =E5/E3 -> 0.14076781 | F27: =F5/F3 -> 0.15061082 | G27: =G5/G3 -> 0.15167199 | H27: =H5/H3 -> 0.14040457 | J27: =MEDIAN(C27:H27) -> 0.14639784 | K27: =AVERAGE(C27:H27) -> 0.14604181 | M27: Maturity | N27: 0.02 | O27: PV(TV) | P27: =P26/((1+N27)^6) -> 570226.6
B28: Operating profit margin | C28: =C10/C3 -> 0.045907635 | D28: =D10/D3 -> 0.052980858 | E28: =E10/E3 -> 0.053041428 | F28: =F10/F3 -> 0.061228065 | G28: =G10/G3 -> 0.068036346 | H28: =H10/H3 -> 0.060627174 | J28: =MEDIAN(C28:H28) -> 0.056834301 | K28: =AVERAGE(C28:H28) -> 0.056970251 | M28: Discount | N28: =WACC!C3 -> 0.072805703 | O28: Share | P28: =P27/Main!K4 -> 7.2054715
B29: Profit margin | C29: =C20/C3 -> 0.037099823 | D29: =D20/D3 -> 0.033450735 | E29: =E20/E3 -> 0.039274714 | F29: =F20/F3 -> 0.046142481 | G29: =G20/G3 -> 0.05114958 | H29: =H20/H3 -> 0.041201423 | J29: =MEDIAN(C29:H29) -> 0.040238069 | K29: =AVERAGE(C29:H29) -> 0.04138646 | M29: NPV | N29: =NPV(N28,I24:JC24) -> 771256.1 | O29: Downside | P29: =(P28-N33)/N33 -> -0.22271074
M30: Cash | N30: =Main!K6 -> 80219
J31: Median growth rates | K31: Average growth rates | M31: Value | N31: =N29+N30 -> 851475.1
B32: Revenue growth y/y | D32: =(D3-C3)/D3 -> 0.032968769 | E32: =(E3-D3)/E3 -> 0.2001756 | F32: =(F3-E3)/F3 -> 0.049783407 | G32: =(G3-F3)/G3 -> 0.037613523 | H32: =(H3-G3)/H3 -> 0.15936153 | J32: =MEDIAN(C32:H32) -> 0.049783407 | K32: =AVERAGE(C32:H32) -> 0.095980564 | M32: Share | N32: =N31/Main!K4 -> 10.759371
B33: Operating profit growth y/y | D33: =(D10-C10)/D10 -> 0.16207253 | E33: =(E10-D10)/E10 -> 0.20108894 | F33: =(F10-E10)/F10 -> 0.17683427 | G33: =(G10-F10)/G10 -> 0.1339179 | H33: =(H10-G10)/H10 -> 0.056628141 | J33: =MEDIAN(C33:H33) -> 0.16207253 | K33: =AVERAGE(C33:H33) -> 0.14610836 | M33: Current | N33: =Main!K3 -> 9.27
B34: Profit growth y/y | D34: =(D20-C20)/D20 -> -0.07252313 | E34: =(E20-D20)/E20 -> 0.31878016 | F34: =(F20-E20)/F20 -> 0.191212 | G34: =(G20-F20)/G20 -> 0.13182279 | H34: =(H20-G20)/H20 -> -0.043612133 | J34: =MEDIAN(C34:H34) -> 0.13182279 | K34: =AVERAGE(C34:H34) -> 0.10513594 | M34: Upside | N34: =(N32-N33)/N33 -> 0.1606657
B36: FCF growth y/y | D36: =(D24-C24)/C24 -> 1.3099606 | E36: =(E24-D24)/D24 -> -0.26972015 | F36: =(F24-E24)/E24 -> 0.48347331 | G36: =(G24-F24)/F24 -> -0.07185215 | H36: =(H24-G24)/G24 -> -0.20829973 | J36: =MEDIAN(C36:H36) -> -0.07185215 | K36: =AVERAGE(D36:H36) -> 0.24871238
B40: Balance sheet
B41: Goodwill+Intangibles | G41: =148805+27869 -> 176674 | H41: =161172+33925 -> 195097
B42: PP&A | G42: 19400 | H42: =25608 -> 25608
B43: ROU | G43: =19174 -> 19174 | H43: =26294 -> 26294
B44: ONCA | G44: =3979+2456 -> 6435 | H44: =3780+2954 -> 6734
B45: Inventories | G45: =4169 -> 4169 | H45: 6365
B46: A/R | G46: 187311 | H46: 183488
B47: OCA | G47: =0+814 -> 814 | H47: =4389+19519 -> 23908
B48: Cash | G48: =35657 -> 35657 | H48: 80219
B49: Assets | G49: =SUM(G41:G48) -> 449634 | H49: =SUM(H41:H48) -> 547713
...

Sheet WACC
B3: WACC | C3: =((Main!K5/(Main!K5+Main!K7))*C5)+((Main!K7/(Main!K5+Main!K7))*C11*(1-C14)) -> 0.072805703 | J3: Cost of Equity = Risk free rate + stock beta * (Market Risk Premium)
J4: Cost of Debt = (Total Interest Expense / Total Debt) x (1 - Tax Rate)
B5: Cost of Equity | C5: =C6+C7*(C9) -> 0.079075 | J5: Total Debt = Short-Term Debt + Long-Term Debt
B6: Risk free rate | C6: 0.0455 | D6: 10y UK bonds yield
B7: Beta | C7: 0.79 | J7: Effective Tax Rate = Income Tax Expense / Earnings Before Taxes
B8: Market return | C8: 0.088 | D8: FTSE100 10y avg | J8: Pre-tax Cost of Debt = Interest Expense / Total Debt
B9: Market premium | C9: =C8-C6 -> 0.0425
B11: Cost of Debt | C11: =(C12/C13)*(1-C14) -> 0.017444257 | J11: WACC = (E/V * Re) + (D/V * Rd * (1-Tc))
B12: Interest expense | C12: =Model!H13 -> 1828 | D12: Y2024
B13: Total debt | C13: =Main!K7 -> 76580 | D13: Y2024 | J13: E = total value of company's equity = market cap
B14: Effective tax rate | C14: =Model!H17/Model!H15 -> 0.26921161 | D14: Y2024 | J14: D = total value of a debt = Total Debt
J15: V = E + D
B16: Debt / Equity (D/E) | C16: =Model!H57/Model!H59 -> 1.6537768 | J16: Re = Cost of Equity
B17: Industry average | C17: =AVERAGE(0.7421,1.036,1.092,1.14) -> 1.002525 | J17: Rd = Cost of Debt
J18: Tc = Tax Rate
B19: * low WACC, however the D/E is higher than industry average - more debt-dependent

Sheet Charts
A1: Main
B2: Date | C2: Price | D2: Open | E2: High | F2: Low | G2: Vol. | H2: Change % | J2: Mean Price | K2: =AVERAGE(C3:C87) -> 685 | M2: Standard Deviation, Price | N2: =_xlfn.STDEV.S(C3:C87) -> 201.93244
B3: 46023 | C3: 919 | D3: 891 | E3: 933 | F3: 874.5 | G3: 2.04M | H3: 0.0314 | J3: Medium Price | K3: =MEDIAN(C3:C87) -> 713 | M3: Variance, Price | N3: =_xlfn.VAR.S(C3:C87) -> 40776.708
B4: 45992 | C4: 891 | D4: 947 | E4: 947 | F4: 870 | G4: 3.16M | H4: -0.046 | J4: Mode Price | K4: =MODE(C3:C87) -> 732
B5: 45962 | C5: 934 | D5: 928 | E5: 978 | F5: 884 | G5: 4.41M | H5: 0.0086 | M5: Standard Deviation, Change, % | N5: =STDEV(H3:H87) -> 0.089248196
B6: 45931 | C6: 926 | D6: 827 | E6: 973 | F6: 825 | G6: 6.14M | H6: 0.1432 | J6: Mean Change | K6: =AVERAGE(H3:H87) -> 0.01558 | M6: Variance, Change, % | N6: =_xlfn.VAR.S(H3:H87) -> 0.0079652404
B7: 45901 | C7: 810 | D7: 808 | E7: 846 | F7: 772 | G7: 3.77M | H7: 0.0112 | J7: Medium Change | K7: =MEDIAN(H3:H87) -> 0.0059
B8: 45870 | C8: 801 | D8: 839 | E8: 875 | F8: 801 | G8: 2.44M | H8: -0.0498 | J8: Mode Change | K8: =MODE(H3:H87) -> 0.0399 | M8: Annualised Return (AAR) | N8: =(919/369)^(1/6)-1 -> 0.16425521
B9: 45839 | C9: 843 | D9: 817 | E9: 867 | F9: 790 | G9: 3.07M | H9: -0.0082
B10: 45809 | C10: 850 | D10: 843 | E10: 867 | F10: 787 | G10: 3.21M | H10: 0.0366
B11: 45778 | C11: 820 | D11: 713 | E11: 859 | F11: 713 | G11: 3.51M | H11: 0.0861 | J11: Price | R11: Change | Y11: Change
B12: 45748 | C12: 755 | D12: 671 | E12: 764 | F12: 604 | G12: 4.47M | H12: 0.1405
B13: 45717 | C13: 662 | D13: 657 | E13: 700 | F13: 631 | G13: 6.52M | H13: 0.0046
B14: 45689 | C14: 659 | D14: 740 | E14: 754 | F14: 654 | G14: 4.83M | H14: -0.0997
B15: 45658 | C15: 732 | D15: 910 | E15: 941 | F15: 690 | G15: 6.54M | H15: -0.1912
B16: 45627 | C16: 905 | D16: 1050 | E16: 1070 | F16: 863 | G16: 2.93M | H16: -0.1298
B17: 45597 | C17: 1040 | D17: 1084 | E17: 1100 | F17: 1016 | G17: 3.15M | H17: -0.0494
B18: 45566 | C18: 1094 | D18: 1098 | E18: 1152 | F18: 1030 | G18: 6.70M | H18: 0.0399
B19: 45536 | C19: 1052 | D19: 1080 | E19: 1110 | F19: 1022 | G19: 3.58M | H19: -0.0187
B20: 45505 | C20: 1072 | D20: 1098 | E20: 1104 | F20: 985 | G20: 2.67M | H20: -0.0129
B21: 45474 | C21: 1086 | D21: 1070 | E21: 1144 | F21: 1016 | G21: 2.79M | H21: 0.0226
B22: 45444 | C22: 1062 | D22: 1050 | E22: 1100 | F22: 1050 | G22: 2.66M | H22: -0.0056
B23: 45413 | C23: 1068 | D23: 961.16 | E23: 1086 | F23: 935.88 | G23: 4.05M | H23: 0.1302
... B87: 43466 | C87: 369 | D87: 330 | E87: 379 | F87: 330 | G87: 1.46M | H87: 0.0869
