Workbook

Sheet Main
B2: * all numbers in thousands, GBP
J3: Price | K3: 9.27 | L3: 927.00 GBX
B4: RENEW HOLDINGS PLC | J4: Shares | K4: 79138 | L4: Q126
B5: Company number: 650447 | J5: MC | K5: =K3*K4 -> 733609.26
B6: LON: RNWH | J6: Cash | K6: 80219 | L6: Y2024
J7: Debt | K7: =15605+52000+8975 -> 76580 | L7: Y2024
B8: Company: Engineering firm specializing in UK (and rest Europe) infrastructure maintenance | J8: EV | K8: =K5+K7-K6 -> 729970.26 | L8: *Strong net cash position
B9: Industry: Industrials
B10: Sector: Construction and Materials | J10: Cash = cash and equivalents
J11: Debt = borrowings + current/non-current lease liabilities (interest-bearing debt)
B12: IPO: 2006
B13: Employees: 4,429 | J13: EBIT | K13: 61171 | L13: Y2024
J14: Earnings | K14: 41571 | L14: Y2024
B16: Low risk business model | J16: EV/EBIT | K16: =K8/K13 -> 11.933273
B17: Markets with committed regulatory funding | J17: EV/E | K17: =K8/K14 -> 17.559603
B18: £600bn UK Government commitment to infrastructure | J18: P/E | K18: =K5/K14 -> 17.64714
B19: Delivering mission-critical infrastructure services across the UK | J19: Debt/EBIT | K19: =K7/K13 -> 1.2519004
B20: Recurring maintenance demand
J21: ROA | K21: =K14/K24 -> 0.075899239 | L21: *higher than market average (~5.6%)
J22: ROE | K22: =K14/(K24-K25) -> 0.20141964 | L22: *slightly lower than market average (~26%)
B23: Core Markets
B24: Rail | C24: providing asset maintenance to the rail network (largest provider in the UK) | J24: Total assets | K24: =Model!H51 -> 547713 | L24: Y2024
B25: Infrastructure | C25: specialist drainage, lighting and electricals at National Highways | J25: Total liabilities | K25: =Model!H60 -> 341323 | L25: Y2024
B26: Energy | C26: risk reduction operations at nuclear facilities
B27: Environmental | C27: asset maintenance and renewals across water infrastructure | J27: Net Tangible Assets | K27: =K24-Model!H43-K25 -> 11293 | L27: =Assets - Intangible assets - Liabilities
J28: NTABPS | K28: =K27/K4 -> 0.14270009 | L28: =NTA / SO
J29: NTABPS/P, % | K29: =K28/K3 -> 0.015393753 | L29: = % of share price backed by tangible net-assets
B30: Risks
B31: Dependency on government contracts and commitments | J31: Book Value | K31: =K24-K25 -> 206390
B32: Operating in complex, challenging and highly regulated environments (both stability factor and risk) | J32: BVPS | K32: =K31/K4 -> 2.6079759
B33: Not the contractor for new large projects, maintance and support mainly | J33: BVPS/P, % | K33: =K32/K3 -> 0.28133505
B34: (Small tangible net-assets position as for a construction company) | J34: Price-to-Book (P/B) | K34: =K5/K31 -> 3.5544806 | L34: *great book value ratio (market average ~5.49)
C36: Paul Scott
B37: CEO | C37: Sean Wyndham-Quin | J37: *Reference for sector based ratios: | L37: https://pages.stern.nyu.edu/~adamodar/New_Home_Page/datafile/pbvdata.html
B38: CFO | C38: David Brown
B39: Chairman

Sheet Model
A1: Main | I1: *Forecast
C2: FY2019 | D2: FY2020 | E2: FY2021 | F2: FY2022 | G2: FY2023 | H2: FY2024 | I2: FY2025 | J2: FY2026 | K2: FY2027 | L2: FY2028 | M2: FY2029 | N2: FY2030
B3: Revenue | C3: 599922 | D3: 620375 | E3: 775639 | F3: 816276 | G3: 848179 | H3: 1008970 | I3: =H3*(1+$Q$28) -> 1105831.1 | J3: =I3*(1+$Q$28) -> 1211990.9 | K3: =J3*(1+$Q$28) -> 1328342 | L3: =K3*(1+$Q$28) -> 1455862.9 | M3: =L3*(1+$Q$28) -> 1595625.7 | N3: =M3*(1+$Q$28) -> 1748805.8
B4: Cost of revenue | C4: 514299 | D4: 527274 | E4: 666454 | F4: 693336 | G4: 719534 | H4: 867306
B5: Gross profit | C5: =C3-C4 -> 85623 | D5: =D3-D4 -> 93101 | E5: =E3-E4 -> 109185 | F5: =F3-F4 -> 122940 | G5: =G3-G4 -> 128645 | H5: =H3-H4 -> 141664
B7: SG&A | C7: 58178 | D7: 60194 | E7: 68055 | F7: 76711 | G7: 74649 | H7: 84459
B8: Other income | C8: 0 | D8: 0 | E8: 0 | F8: 3655 | G8: 3865 | H8: 4165
B9: Joint ventures post-tax (loss) | C9: -96 | D9: 39 | E9: -11 | F9: -95 | G9: 154 | H9: 199
B10: Operating profit | C10: =C5-C7-C9+C8 -> 27541 | D10: =D5-D7-D9+D8 -> 32868 | E10: =E5-E7-E9+E8 -> 41141 | F10: =F5-F7-F9+F8 -> 49979 | G10: =G5-G7-G9+G8 -> 57707 | H10: =H5-H7-H9+H8 -> 61171 | I10: =I3*$J$29 -> 62849.139 | J10: =J3*$J$29 -> 68882.656 | K10: =K3*$J$29 -> 75495.391 | L10: =L3*$J$29 -> 82742.949 | M10: =M3*$J$29 -> 90686.272 | N10: =N3*$J$29 -> 99392.154
B12: Finance income | C12: 50 | D12: 44 | E12: 19 | F12: 16 | G12: 360 | H12: 791
B13: Finance costs | C13: 1244 | D13: 1343 | E13: 836 | F13: 573 | G13: 1285 | H13: 1828
B14: Other finance income | C14: 615 | D14: 532 | E14: 428 | F14: 33 | G14: 66 | H14: 90
B15: Pretax profit | C15: =C10+C12-C13+C14 -> 26962 | D15: =D10+D12-D13+D14 -> 32101 | E15: =E10+E12-E13+E14 -> 40752 | F15: =F10+F12-F13+F14 -> 49455 | G15: =G10+G12-G13+G14 -> 56848 | H15: =H10+H12-H13+H14 -> 60224
B17: Taxes | C17: 4705 | D17: 5759 | E17: 8669 | F17: 9548 | G17: 10742 | H17: 16213
B18: Profit continued activities | C18: =C15-C17 -> 22257 | D18: =D15-D17 -> 26342 | E18: =E15-E17 -> 32083 | F18: =F15-F17 -> 39907 | G18: =G15-G17 -> 46106 | H18: =H15-H17 -> 44011
B19: Loss from discontinued operations | C19: 0 | D19: 5590 | E19: 1620 | F19: 2242 | G19: 2722 | H19: 2440
B20: Profit (net income) | C20: =C18-C19 -> 22257 | D20: 26342 | E20: 32083 | F20: 39907 | G20: 46106 | H20: 44011 | I20: =I3*$J$30 -> 47595.605 | J20: =J3*$J$30 -> 52164.783 | K20: =K3*$J$30 -> 57172.602 | L20: =L3*$J$30 -> 62661.172 | M20: =M3*$J$30 -> 68676.644 | N20: =N3*$J$30 -> 75269.602
B21: EPS | C21: =C20/Main!$K$4 -> 0.28124289 | D21: =D20/Main!$K$4 -> 0.33286158 | E21: =E20/Main!$K$4 -> 0.40540575 | F21: =F20/Main!$K$4 -> 0.50427102 | G21: =G20/Main!$K$4 -> 0.58260254 | H21: =H20/Main!$K$4 -> 0.5561298 | I21: =I20/Main!$K$4 -> 0.60142542 | J21: =J20/Main!$K$4 -> 0.65916226 | ... N21: =N20/Main!$K$4 -> 0.95111833
B23: OCF | C23: 23370 | D23: 52446 | E23: 40143 | F23: 61140 | G23: 57017 | H23: 48467
B24: CapEx (PP&E) | C24: =2619 -> 2619 | D24: 3756 | E24: =4042 -> 4042 | F24: =5056 -> 5056 | G24: 5414 | H24: 6146
B25: FCF | C25: =C23-C24 -> 20751 | D25: =D23-D24 -> 48690 | E25: =E23-E24 -> 36101 | F25: =F23-F24 -> 56084 | G25: =G23-G24 -> 51603 | H25: =H23-H24 -> 42321 | I25: =I3*$K$31 -> 61025.199 | J25: =J3*$K$31 -> 66883.618 | K25: =K3*$K$31 -> 73304.445 | L25: =L3*$K$31 -> 80341.672 | M25: =M3*$K$31 -> 88054.473 | N25: =N3*$K$31 -> 96507.702 | O25: =N25*(1+$Q$29) -> 95542.625 | P25: =O25*(1+$Q$29) -> 94587.199 | Q25: =P25*(1+$Q$29) -> 93641.327 | R25: =Q25*(1+$Q$29) -> 92704.914 | S25: =R25*(1+$Q$29) -> 91777.864 | T25: =S25*(1+$Q$29) -> 90860.086 | U25: =T25*(1+$Q$29) -> 89951.485 | V25: =U25*(1+$Q$29) -> 89051.97 | ... GJ25: =GI25*(1+$Q$29) -> 16129.712
J27: Median margins | K27: Average margins | M27: Bull Case* | P27: Base Case* | S27: Bear Case*
B28: Gross margin | C28: =C5/C3 -> 0.14272355 | D28: =D5/D3 -> 0.15007213 | E28: =E5/E3 -> 0.14076781 | F28: =F5/F3 -> 0.15061082 | G28: =G5/G3 -> 0.15167199 | H28: =H5/H3 -> 0.14040457 | J28: =MEDIAN(C28:H28) -> 0.14639784 | K28: =AVERAGE(C28:H28) -> 0.14604181 | M28: 5Y revenue growth | N28: 0.15 | P28: 5Y revenue growth | Q28: 0.096 | S28: 5Y revenue growth | T28: 0.034
B29: Operating profit margin | C29: =C10/C3 -> 0.045907635 | D29: =D10/D3 -> 0.052980858 | E29: =E10/E3 -> 0.053041428 | F29: =F10/F3 -> 0.061228065 | G29: =G10/G3 -> 0.068036346 | H29: =H10/H3 -> 0.060627174 | J29: =MEDIAN(C29:H29) -> 0.056834301 | K29: =AVERAGE(C29:H29) -> 0.056970251 | M29: Maturity | N29: -0.01 | P29: Maturity | Q29: -0.01 | S29: Maturity | T29: -0.01
B30: Profit margin | C30: =C20/C3 -> 0.037099823 | D30: =D20/D3 -> 0.042461414 | E30: =E20/E3 -> 0.041363315 | F30: =F20/F3 -> 0.048889101 | G30: =G20/G3 -> 0.054358809 | H30: =H20/H3 -> 0.043619731 | J30: =MEDIAN(C30:H30) -> 0.043040573 | K30: =AVERAGE(C30:H30) -> 0.044632032 | M30: WACC | N30: =WACC!C2 -> 0.080502274 | P30: WACC | Q30: =WACC!C2 -> 0.080502274 | S30: WACC | T30: =WACC!C2 -> 0.080502274
B31: FCF margin | C31: =C25/C3 -> 0.034589497 | D31: =D25/D3 -> 0.078484787 | E31: =E25/E3 -> 0.04654356 | F31: =F25/F3 -> 0.068707153 | G31: =G25/G3 -> 0.060839752 | H31: =H25/H3 -> 0.041944756 | J31: =MEDIAN(C31:H31) -> 0.053691656 | K31: =AVERAGE(C31:H31) -> 0.055184917 | M31: Risk Premiums | N31: 0.015 | P31: Risk Premiums | Q31: 0.02 | S31: Risk Premiums | T31: 0.025
B32: SG&A % of revenue | C32: =C7/C3 -> 0.09697594 | D32: =D7/D3 -> 0.09702841 | E32: =E7/E3 -> 0.08774056 | F32: =F7/F3 -> 0.093976792 | G32: =G7/G3 -> 0.088010903 | H32: =H7/H3 -> 0.083708138 | J32: =MEDIAN(C32:H32) -> 0.090993848 | K32: =AVERAGE(C32:H32) -> 0.091240124 | M32: Discount | N32: =N31+N30 -> 0.095502274 | P32: Discount | Q32: =Q31+Q30 -> 0.10050227 | S32: Discount | T32: =T31+T30 -> 0.10550227
M33: NPV | N33: =NPV(N32,I72:FJ72) -> 1096481.7 | P33: NPV | Q33: =NPV(Q32,I25:XFD25) -> 816049.62 | S33: NPV | T33: =NPV(T32,O75:FB75) -> 493473.45
J34: Median growth rates | K34: Average growth rates | M34: Share | N34: =N33/Main!K4 -> 13.855313 | P34: Share | Q34: =Q33/Main!K4 -> 10.311729 | S34: Share | T34: =T33/Main!K4 -> 6.2356069
B35: Revenue growth y/y | D35: =(D3-C3)/D3 -> 0.032968769 | E35: =(E3-D3)/E3 -> 0.2001756 | F35: =(F3-E3)/F3 -> 0.049783407 | G35: =(G3-F3)/G3 -> 0.037613523 | H35: =(H3-G3)/H3 -> 0.15936153 | J35: =MEDIAN(C35:H35) -> 0.049783407 | K35: =AVERAGE(C35:H35) -> 0.095980564 | M35: Current | N35: =Main!K3 -> 9.27 | P35: Current | Q35: =Main!K3 -> 9.27 | S35: Current | T35: =Main!K3 -> 9.27
B36: Operating profit growth y/y | D36: =(D10-C10)/D10 -> 0.16207253 | E36: =(E10-D10)/E10 -> 0.20108894 | F36: =(F10-E10)/F10 -> 0.17683427 | G36: =(G10-F10)/G10 -> 0.1339179 | H36: =(H10-G10)/H10 -> 0.056628141 | J36: =MEDIAN(C36:H36) -> 0.16207253 | K36: =AVERAGE(C36:H36) -> 0.14610836 | M36: Upside | N36: =(N34-N35)/N35 -> 0.49463999 | P36: Upside | Q36: =(Q34-Q35)/Q35 -> 0.1123764 | S36: Upside | T36: =(T34-T35)/T35 -> -0.32733475
B37: Profit growth y/y | D37: =(D20-C20)/D20 -> 0.15507554 | E37: =(E20-D20)/E20 -> 0.17894212 | F37: =(F20-E20)/F20 -> 0.19605583 | G37: =(G20-F20)/G20 -> 0.13445105 | H37: =(H20-G20)/H20 -> -0.047601736 | J37: =MEDIAN(C37:H37) -> 0.15507554 | K37: =AVERAGE(C37:H37) -> 0.12338456
M38: *if company accelerates in revenue growth | P38: *if company continues to grow at a current rate | S38: *if the company flattens (grows at inflation rate)
B39: FCF growth y/y | D39: =(D25-C25)/C25 -> 1.3463929 | E39: =(E25-D25)/D25 -> -0.25855412 | F39: =(F25-E25)/E25 -> 0.55353037 | G39: =(G25-F25)/F25 -> -0.07989801 | H39: =(H25-G25)/G25 -> -0.17987326 | J39: =MEDIAN(C39:H39) -> -0.07989801 | K39: =AVERAGE(D39:H39) -> 0.27631959
M40: Risk Premiums: (1) liquidity risk (equal in all cases); (2) equity risk premium (increases slightly in case of slower revenue growth due to insignificant leverage, debt/ebit)
B42: Balance sheet | M42: Maturity: assumes that the company constantly falls at a relatively small rate (-1%) after the forecasting period
B43: Goodwill+Intangibles | G43: =148805+27869 -> 176674 | H43: =161172+33925 -> 195097
B44: PP&E | G44: 19400 | H44: =25608 -> 25608 | M44: NOT forcasting, but determining how market values the company considering different scenarios of revenue growth
B45: ROU | G45: =19174 -> 19174 | H45: =26294 -> 26294
B46: ONCA | G46: =3979+2456 -> 6435 | H46: =3780+2954 -> 6734
...

Sheet WACC
A1: Main
B2: WACC | C2: =((Main!K5/(Main!K5+Main!K7))*C4)+((Main!K7/(Main!K5+Main!K7))*C10*(1-C13)) -> 0.080502274 | H2: Cost of Equity = Risk free rate + stock beta * (Market Risk Premium)
H3: Cost of Debt = (Total Interest Expense / Total Debt) x (1 - Tax Rate)
B4: Cost of Equity | C4: =C5+C6*(C8) -> 0.087575 | H4: Total Debt = Short-Term Debt + Long-Term Debt
B5: Risk free rate | C5: 0.0455 | D5: 10y UK bonds yield
B6: Beta | C6: 0.99 | D6: regression | H6: Effective Tax Rate = Income Tax Expense / Earnings Before Taxes
B7: Market return | C7: 0.088 | D7: FTSE100 10y avg | H7: Pre-tax Cost of Debt = Interest Expense / Total Debt
B8: Market premium | C8: =C7-C5 -> 0.0425
B10: Cost of Debt | C10: =(C11/C12)*(1-C13) -> 0.017444257 | H10: WACC = (E/V * Re) + (D/V * Rd * (1-Tc))
B11: Interest expense | C11: =Model!H13 -> 1828 | D11: FY2024
B12: Total debt | C12: =Main!K7 -> 76580 | D12: FY2024 | H12: E = total value of company's equity = market cap
B13: Effective tax rate | C13: =Model!H17/Model!H15 -> 0.26921161 | D13: FY2024 | H13: D = total value of a debt = Total Debt
H14: V = E + D
B15: Debt / Equity (D/E) | C15: =Model!H60/Model!H62 -> 1.6537768 | H15: Re = Cost of Equity
B16: Industry average | C16: =AVERAGE(0.7421,1.036,1.092,1.14) -> 1.002525 | H16: Rd = Cost of Debt
H17: Tc = Tax Rate
B18: * low WACC, however the D/E is higher than industry average - more debt-dependent

Sheet Charts
A1: Main
B2: Date | C2: RNWH | D2: FTSE100 | E2: Base RNWH | F2: Base FTSE100 | G2: RNWH Change | H2: FTSE100 Change | I2: Inflation (CPI) MoM | J2: Rate Change Abs. | K2: Interest Rate, % | L2: Rate Change m/m, %
B3: 43466 | C3: 369 | D3: 6968.85 | E3: =C3/$C$3*100 -> 100 | F3: =D3/$D$3*100 -> 100 | I3: 0.004 | K3: 0.75
B4: 43497 | C4: 377 | D4: 7074.73 | E4: =C4/$C$3*100 -> 102.16802 | F4: =D4/$D$3*100 -> 101.51933 | G4: =C4/C3-1 -> 0.021680217 | H4: =D4/D3-1 -> 0.015193325 | I4: 0.004 | J4: =K4-K3 -> 0 | K4: 0.75 | L4: =K4/K3-1 -> 0
B5: 43525 | C5: 402 | D5: 7279.19 | E5: =C5/$C$3*100 -> 108.94309 | F5: =D5/$D$3*100 -> 104.45325 | G5: =C5/C4-1 -> 0.066312997 | H5: =D5/D4-1 -> 0.028900043 | I5: -0.002 | J5: =K5-K4 -> 0 | K5: 0.75 | L5: =K5/K4-1 -> 0
B6: 43556 | C6: 390.5 | D6: 7418.22 | E6: =C6/$C$3*100 -> 105.82656 | F6: =D6/$D$3*100 -> 106.44827 | G6: =C6/C5-1 -> -0.028606965 | H6: =D6/D5-1 -> 0.019099653 | I6: 0.004 | J6: =K6-K5 -> 0 | K6: 0.75 | L6: =K6/K5-1 -> 0
B7: 43586 | C7: 430 | D7: 7161.71 | E7: =C7/$C$3*100 -> 116.53117 | F7: =D7/$D$3*100 -> 102.76746 | G7: =C7/C6-1 -> 0.10115237 | H7: =D7/D6-1 -> -0.034578376 | I7: 0 | J7: =K7-K6 -> 0 | K7: 0.75 | L7: =K7/K6-1 -> 0
B8: 43617 | C8: 415 | D8: 7425.63 | E8: =C8/$C$3*100 -> 112.46612 | F8: =D8/$D$3*100 -> 106.5546 | G8: =C8/C7-1 -> -0.034883721 | H8: =D8/D7-1 -> 0.036851534 | I8: 0.003 | J8: =K8-K7 -> 0 | K8: 0.75 | L8: =K8/K7-1 -> 0
B9: 43647 | C9: 400 | D9: 7586.78 | E9: =C9/$C$3*100 -> 108.40108 | F9: =D9/$D$3*100 -> 108.86703 | G9: =C9/C8-1 -> -0.036144578 | H9: =D9/D8-1 -> 0.021701862 | I9: 0.001 | J9: =K9-K8 -> 0 | K9: 0.75 | L9: =K9/K8-1 -> 0
B10: 43678 | C10: 386.5 | D10: 7207.18 | E10: =C10/$C$3*100 -> 104.74255 | F10: =D10/$D$3*100 -> 103.41993 | G10: =C10/C9-1 -> -0.03375 | H10: =D10/D9-1 -> -0.050034402 | I10: 0.003 | J10: =K10-K9 -> 0 | K10: 0.75 | L10: =K10/K9-1 -> 0
B11: 43709 | C11: 385 | D11: 7408.21 | E11: =C11/$C$3*100 -> 104.33604 | F11: =D11/$D$3*100 -> 106.30463 | G11: =C11/C10-1 -> -0.0038809832 | H11: =D11/D10-1 -> 0.027893018 | I11: 0.002 | J11: =K11-K10 -> 0 | K11: 0.75 | L11: =K11/K10-1 -> 0
B12: 43739 | C12: 383 | D12: 7248.38 | E12: =C12/$C$3*100 -> 103.79404 | F12: =D12/$D$3*100 -> 104.01114 | G12: =C12/C11-1 -> -0.0051948052 | H12: =D12/D11-1 -> -0.021574712 | I12: 0.012 | J12: =K12-K11 -> 0 | K12: 0.75 | L12: =K12/K11-1 -> 0
B13: 43770 | C13: 390 | D13: 7346.53 | E13: =C13/$C$3*100 -> 105.69106 | F13: =D13/$D$3*100 -> 105.41955 | G13: =C13/C12-1 -> 0.018276762 | H13: =D13/D12-1 -> 0.013540957 | I13: 0.003 | J13: =K13-K12 -> 0 | K13: 0.75 | L13: =K13/K12-1 -> 0
B14: 43800 | C14: 546 | D14: 7542.44 | E14: =C14/$C$3*100 -> 147.96748 | F14: =D14/$D$3*100 -> 108.23077 | G14: =C14/C13-1 -> 0.4 | H14: =D14/D13-1 -> 0.026667012 | I14: 0.004 | J14: =K14-K13 -> 0 | K14: 0.75 | L14: =K14/K13-1 -> 0
B15: 43831 | C15: 500 | D15: 7286.01 | E15: =C15/$C$3*100 -> 135.50136 | F15: =D15/$D$3*100 -> 104.55111 | G15: =C15/C14-1 -> -0.084249084 | H15: =D15/D14-1 -> -0.033998282 | I15: -0.001 | J15: =K15-K14 -> 0 | K15: 0.75 | L15: =K15/K14-1 -> 0
... B28: 44228 | C28: 502 | D28: 6483.43 | E28: =C28/$C$3*100 -> 136.04336 | F28: =D28/$D$3*100 -> 93.034432 | G28: =C28/C27-1 -> -0.041984733 | H28: =D28/D27-1 -> 0.011856492 | I28: 0.004 | J28: =K28-K27 -> 0 | K28: 0.1 | L28: =K28/K27-1 -> 0
B29: 44256 | C29: 564 | D29: 6713.63 | E29: =C29/$C$3*100 -> 152.84553 | F29: =D29/$D$3*100 -> 96.337703 | G29: =C29/C28-1 -> 0.12350598 | H29: =D29/D28-1 -> 0.035505897 | I29: -0.002 | J29: =K29-K28 -> 0 | K29: 0.1 | L29: =K29/K28-1 -> 0 | N29: Correlation | O29: =CORREL(C3:C87, D3:D87) -> 0.67265299 | P29: Stock returns and FTSE 100
B30: 44287 | C30: 625 | D30: 6969.81 | E30: =C30/$C$3*100 -> 169.37669 | F30: =D30/$D$3*100 -> 100.01378 | G30: =C30/C29-1 -> 0.10815603 | H30: =D30/D29-1 -> 0.038158195 | I30: 0 | J30: =K30-K29 -> 0 | K30: 0.1 | L30: =K30/K29-1 -> 0
B31: 44317 | C31: 636 | D31: 7022.61 | E31: =C31/$C$3*100 -> 172.35772 | F31: =D31/$D$3*100 -> 100.77143 | G31: =C31/C30-1 -> 0.0176 | H31: =D31/D30-1 -> 0.0075755293 | I31: 0.005 | J31: =K31-K30 -> 0 | K31: 0.1 | L31: =K31/K30-1 -> 0
B32: 44348 | C32: 675 | D32: 7037.47 | E32: =C32/$C$3*100 -> 182.92683 | F32: =D32/$D$3*100 -> 100.98467 | G32: =C32/C31-1 -> 0.061320755 | H32: =D32/D31-1 -> 0.0021160224 | I32: 0.003 | J32: =K32-K31 -> 0 | K32: 0.1 | L32: =K32/K31-1 -> 0
B33: 44378 | C33: 746 | D33: 7032.3 | E33: =C33/$C$3*100 -> 202.16802 | F33: =D33/$D$3*100 -> 100.91048 | G33: =C33/C32-1 -> 0.10518519 | H33: =D33/D32-1 -> -0.00073463901 | I33: -0.004 | J33: =K33-K32 -> 0 | K33: 0.1 | L33: =K33/K32-1 -> 0
B34: 44409 | C34: 767 | D34: 7119.7 | E34: =C34/$C$3*100 -> 207.85908 | F34: =D34/$D$3*100 -> 102.16463 | G34: =C34/C33-1 -> 0.028150134 | H34: =D34/D33-1 -> 0.012428366 | I34: 0.001 | J34: =K34-K33 -> 0 | K34: 0.1 | L34: =K34/K33-1 -> 0
B35: 44440 | C35: 790 | D35: 7086.42 | E35: =C35/$C$3*100 -> 214.09214 | F35: =D35/$D$3*100 -> 101.68708 | G35: =C35/C34-1 -> 0.029986962 | H35: =D35/D34-1 -> -0.0046743543 | I35: 0.007 | J35: =K35-K34 -> 0 | K35: 0.1 | L35: =K35/K34-1 -> 0
B36: 44470 | C36: 763 | D36: 7237.57 | E36: =C36/$C$3*100 -> 206.77507 | F36: =D36/$D$3*100 -> 103.85602 | G36: =C36/C35-1 -> -0.034177215 | H36: =D36/D35-1 -> 0.021329529 | I36: 0.012 | J36: =K36-K35 -> 0 | K36: 0.1 | L36: =K36/K35-1 -> 0
B37: 44501 | C37: 803 | D37: 7059.45 | E37: =C37/$C$3*100 -> 217.61518 | F37: =D37/$D$3*100 -> 101.30007 | G37: =C37/C36-1 -> 0.05242464 | H37: =D37/D36-1 -> -0.02461047 | I37: 0.008 | J37: =K37-K36 -> 0 | K37: 0.1 | L37: =K37/K36-1 -> 0
B38: 44531 | C38: 835 | D38: 7384.54 | E38: =C38/$C$3*100 -> 226.28726 | F38: =D38/$D$3*100 -> 105.96497 | G38: =C38/C37-1 -> 0.03985056 | H38: =D38/D37-1 -> 0.04605033 | I38: 0.011 | J38: =K38-K37 -> 0 | K38: 0.1 | L38: =K38/K37-1 -> 0
B39: 44562 | C39: 720 | D39: 7464.37 | E39: =C39/$C$3*100 -> 195.12195 | F39: =D39/$D$3*100 -> 107.1105 | G39: =C39/C38-1 -> -0.13772455 | H39: =D39/D38-1 -> 0.010810423 | I39: -0.006 | J39: =K39-K38 -> 0.15 | K39: 0.25 | L39: =K39/K38-1 -> 1.5
B40: 44593 | C40: 680 | D40: 7458.25 | E40: =C40/$C$3*100 -> 184.28184 | F40: =D40/$D$3*100 -> 107.02268 | G40: =C40/C39-1 -> -0.055555556 | H40: =D40/D39-1 -> -0.00081989505 | I40: 0.004 | J40: =K40-K39 -> 0 | K40: 0.25 | L40: =K40/K39-1 -> 0
B41: 44621 | C41: 684 | D41: 7515.68 | E41: =C41/$C$3*100 -> 185.36585 | F41: =D41/$D$3*100 -> 107.84678 | G41: =C41/C40-1 -> 0.0058823529 | H41: =D41/D40-1 -> 0.0077001978 | I41: 0.004 | J41: =K41-K40 -> 0.25 | K41: 0.5 | L41: =K41/K40-1 -> 1
... B60: 45200 | C60: 717 | D60: 7321.72 | E60: =C60/$C$3*100 -> 194.30894 | F60: =D60/$D$3*100 -> 105.06353 | G60: =C60/C59-1 -> 0.0056100982 | H60: =D60/D59-1 -> -0.037638931 | I60: 0.006 | J60: =K60-K59 -> 0 | K60: 5.25 | L60: =K60/K59-1 -> 0
B61: 45231 | C61: 842 | D61: 7453.75 | E61: =C61/$C$3*100 -> 228.18428 | F61: =D61/$D$3*100 -> 106.95811 | G61: =C61/C60-1 -> 0.17433752 | H61: =D61/D60-1 -> 0.018032648 | I61: 0.003 | J61: =K61-K60 -> 0 | K61: 5.25 | L61: =K61/K60-1 -> 0 | N61: Correlation | O61: =CORREL(G3:G87, I3:I87) -> 0.15262321 | P61: Stock returns and Inflation | W61: Correlation | X61: =CORREL(G4:G87, L4:L87) -> -0.23239373 | Y61: Stock returns and Interest Rate
B62: 45261 | C62: 859 | D62: 7733.24 | E62: =C62/$C$3*100 -> 232.79133 | F62: =D62/$D$3*100 -> 110.96867 | G62: =C62/C61-1 -> 0.020190024 | H62: =D62/D61-1 -> 0.037496562 | I62: 0.001 | J62: =K62-K61 -> 0 | K62: 5.25 | L62: =K62/K61-1 -> 0
B63: 45292 | C63: 880 | D63: 7630.57 | E63: =C63/$C$3*100 -> 238.48238 | F63: =D63/$D$3*100 -> 109.4954 | G63: =C63/C62-1 -> 0.024447031 | H63: =D63/D62-1 -> -0.013276453 | I63: -0.002 | J63: =K63-K62 -> 0 | K63: 5.25 | L63: =K63/K62-1 -> 0
B64: 45323 | C64: 875 | D64: 7630.02 | E64: =C64/$C$3*100 -> 237.12737 | F64: =D64/$D$3*100 -> 109.48751 | G64: =C64/C63-1 -> -0.0056818182 | H64: =D64/D63-1 -> -7.2078495e-05 | I64: 0.003 | J64: =K64-K63 -> 0 | K64: 5.25 | L64: =K64/K63-1 -> 0
B65: 45352 | C65: 924 | D65: 7952.62 | E65: =C65/$C$3*100 -> 250.4065 | F65: =D65/$D$3*100 -> 114.11668 | G65: =C65/C64-1 -> 0.056 | H65: =D65/D64-1 -> 0.042280361 | I65: -0.001 | J65: =K65-K64 -> 0 | K65: 5.25 | L65: =K65/K64-1 -> 0 | N65: Regression
B66: 45383 | C66: 945 | D66: 8144.13 | E66: =C66/$C$3*100 -> 256.09756 | F66: =D66/$D$3*100 -> 116.86476 | G66: =C66/C65-1 -> 0.022727273 | H66: =D66/D65-1 -> 0.024081372 | I66: 0 | J66: =K66-K65 -> 0 | K66: 5.25 | L66: =K66/K65-1 -> 0 | N66: Dependent: | O66: RNWH monthly return
B67: 45413 | C67: 1068 | D67: 8275.38 | E67: =C67/$C$3*100 -> 289.43089 | F67: =D67/$D$3*100 -> 118.74814 | G67: =C67/C66-1 -> 0.13015873 | H67: =D67/D66-1 -> 0.016115902 | I67: 0.004 | J67: =K67-K66 -> 0 | K67: 5.25 | L67: =K67/K66-1 -> 0 | N67: Independent: | O67: FTSE return (market factor)
B68: 45444 | C68: 1062 | D68: 8164.12 | E68: =C68/$C$3*100 -> 287.80488 | F68: =D68/$D$3*100 -> 117.15161 | G68: =C68/C67-1 -> -0.0056179775 | H68: =D68/D67-1 -> -0.0134447 | I68: -0.004 | J68: =K68-K67 -> 0 | K68: 5.25 | L68: =K68/K67-1 -> 0 | O68: Inflation (macro factor)
B69: 45474 | C69: 1086 | D69: 8367.98 | E69: =C69/$C$3*100 -> 294.30894 | F69: =D69/$D$3*100 -> 120.07691 | G69: =C69/C68-1 -> 0.02259887 | H69: =D69/D68-1 -> 0.024970236 | I69: 0.004 | J69: =K69-K68 -> 0 | K69: 5.25 | L69: =K69/K68-1 -> 0 | O69: Interest rate change (monetary factor)
B70: 45505 | C70: 1072 | D70: 8376.63 | E70: =C70/$C$3*100 -> 290.51491 | F70: =D70/$D$3*100 -> 120.20104 | G70: =C70/C69-1 -> -0.012891344 | H70: =D70/D69-1 -> 0.0010337023 | I70: 0.001 | J70: =K70-K69 -> -0.25 | K70: 5 | L70: =K70/K69-1 -> -0.047619048
...

Sheet Regression
A1: SUMMARY OUTPUT
A3: Regression Statistics
A4: Multiple R | B4: 0.45058722
A5: R Square | B5: 0.20302884
A6: Adjusted R Square | B6: 0.17276411
A7: Standard Error | B7: 0.081836737
A8: Observations | B8: 83
A10: ANOVA
B11: df | C11: SS | D11: MS | E11: F | F11: Significance F
A12: Regression | B12: 3 | C12: 0.13478415 | D12: 0.044928052 | E12: 6.7084312 | F12: 0.00043183211
A13: Residual | B13: 79 | C13: 0.52908288 | D13: 0.0066972516
A14: Total | B14: 82 | C14: 0.66386703
B16: Coefficients | C16: Standard Error | D16: t Stat | E16: P-value | F16: Lower 95% | G16: Upper 95% | H16: Lower 95.0% | I16: Upper 95.0%
A17: Intercept | B17: 0.0021216595 | C17: 0.010687061 | D17: 0.19852601 | E17: 0.84314355 | F17: -0.019150402 | G17: 0.023393722 | H17: -0.019150402 | I17: 0.023393722
A18: 0.015193325 | B18: 0.99432286 | C18: 0.25017573 | D18: 3.9744976 | E18: 0.0001549463 | F18: 0.49636052 | G18: 1.4922852 | H18: 0.49636052 | I18: 1.4922852
A19: 0.004 | B19: 2.9504032 | C19: 1.8817651 | D19: 1.5678914 | E19: 0.12090352 | F19: -0.79515648 | G19: 6.6959629 | H19: -0.79515648 | I19: 6.6959629
A20: 0 | B20: -0.054522914 | C20: 0.050072457 | D20: -1.0888803 | E20: 0.27951725 | F20: -0.15418965 | G20: 0.045143818 | H20: -0.15418965 | I20: 0.045143818
A24: RESIDUAL OUTPUT
A26: Observation | B26: Predicted 0.0216802168021679 | C26: Residuals
A27: 1 | B27: 0.024956826 | C27: 0.041356171
A28: 2 | B28: 0.032914493 | C28: -0.061521459
A29: 3 | B29: -0.03226041 | C29: 0.13341278
A30: 4 | B30: 0.047615192 | C30: -0.082498913
A31: 5 | B31: 0.026650721 | C31: -0.062795299
A32: 6 | B32: -0.03877748 | C32: 0.0050274804
A33: 7 | B33: 0.035757131 | C33: -0.039638114
A34: 8 | B34: 0.016074268 | C34: -0.021269074
A35: 9 | B35: 0.024436952 | C35: -0.0061601896
A36: 10 | B36: 0.040438891 | C36: 0.35956111
A37: 11 | B37: -0.034634012 | C37: -0.049615072
A38: 12 | B38: -0.085293173 | C38: 0.073293173
... A109: 83 | B109: 0.021400018 | C109: 0.010025346

Sheet _RNWHabs&InterestRate
A1: SUMMARY OUTPUT
A3: Regression Statistics
A4: Multiple R | B4: 0.72855649
A5: R Square | B5: 0.53079455
A6: Adjusted R Square | B6: 0.52507254
A7: Standard Error | B7: 137.91709
A8: Observations | B8: 84
A10: ANOVA
B11: df | C11: SS | D11: MS | E11: F | F11: Significance F
A12: Regression | B12: 1 | C12: 1764466.6 | D12: 1764466.6 | E12: 92.76353 | F12: 4.0056399e-15
A13: Residual | B13: 82 | C13: 1559732.2 | D13: 19021.124
A14: Total | B14: 83 | C14: 3324198.7
B16: Coefficients | C16: Standard Error | D16: t Stat | E16: P-value | F16: Lower 95% | G16: Upper 95% | H16: Lower 95.0% | I16: Upper 95.0%
A17: Intercept | B17: 524.72388 | C17: 22.727032 | D17: 23.088096 | E17: 1.2437544e-37 | F17: 479.51257 | G17: 569.93518 | H17: 479.51257 | I17: 569.93518
A18: 0.75 | B18: 68.947683 | C18: 7.1586486 | D18: 9.6313826 | E18: 4.0056399e-15 | F18: 54.706851 | G18: 83.188515 | H18: 54.706851 | I18: 83.188515
A22: RESIDUAL OUTPUT
A24: Observation | B24: Predicted 369 | C24: Residuals
A25: 1 | B25: 576.43464 | C25: -199.43464
A26: 2 | B26: 576.43464 | C26: -174.43464
A27: 3 | B27: 576.43464 | C27: -185.93464
A28: 4 | B28: 576.43464 | C28: -146.43464
A29: 5 | B29: 576.43464 | C29: -161.43464
A30: 6 | B30: 576.43464 | C30: -176.43464
A31: 7 | B31: 576.43464 | C31: -189.93464
A32: 8 | B32: 576.43464 | C32: -191.43464
A33: 9 | B33: 576.43464 | C33: -193.43464
A34: 10 | B34: 576.43464 | C34: -186.43464
A35: 11 | B35: 576.43464 | C35: -30.434638
A36: 12 | B36: 576.43464 | C36: -76.434638
... A108: 84 | B108: 783.27769 | C108: 135.72231

Sheet Statistics_RNWH&FTSE100 
A1: Main
B2: RNWH | J2: FTSE 100
B3: Date | C3: Price | D3: Open | E3: High | F3: Low | G3: Vol. | H3: Change % | J3: Date | K3: Price | L3: Open | M3: High | N3: Low | O3: Vol. | P3: Change % | R3: Mean Price | S3: =AVERAGE(C4:C88) -> 685 | U3: RNWH Standard Deviation, Price | V3: =_xlfn.STDEV.S(C4:C88) -> 201.93244 | X3: Minimum | Y3: =MIN(H4:H88) -> -0.2389
B4: 46023 | C4: 919 | D4: 891 | E4: 933 | F4: 874.5 | G4: 2.04M | H4: 0.0314 | J4: 46023 | K4: 10223.54 | L4: 9931.29 | M4: 10277.72 | N4: 9930.76 | O4: 16.01B | P4: 0.0294 | R4: Median Price | S4: =MEDIAN(C4:C88) -> 713 | U4: RNWH Variance, Price | V4: =_xlfn.VAR.S(C4:C88) -> 40776.708 | X4: Maximum | Y4: =MAX(H4:H88) -> 0.4
B5: 45992 | C5: 891 | D5: 947 | E5: 947 | F5: 870 | G5: 3.16M | H5: -0.046 | J5: 45992 | K5: 9931.38 | L5: 9720.55 | M5: 9954.32 | N5: 9622.74 | O5: 13.99B | P5: 0.0217 | R5: Mode Price | S5: =MODE(C4:C88) -> 732
B6: 45962 | C6: 934 | D6: 928 | E6: 978 | F6: 884 | G6: 4.41M | H6: 0.0086 | J6: 45962 | K6: 9720.51 | L6: 9717.26 | M6: 9930.09 | N6: 9423.9 | O6: 16.80B | P6: 0.0003 | U6: RNWH Standard Deviation, Change, % | V6: =_xlfn.STDEV.S(H4:H88) -> 0.089248196 | X6: Count | Y6: =COUNT(H4:H88) -> 85
B7: 45931 | C7: 926 | D7: 827 | E7: 973 | F7: 825 | G7: 6.14M | H7: 0.1432 | J7: 45931 | K7: 9717.25 | L7: 9350.46 | M7: 9787.63 | N7: 9276.91 | O7: 16.48B | P7: 0.0392 | R7: RNWH Mean Change | S7: =AVERAGE(H4:H88) -> 0.01558 | U7: RNWH Variance, Change, % | V7: =_xlfn.VAR.S(H4:H88) -> 0.0079652404
B8: 45901 | C8: 810 | D8: 808 | E8: 846 | F8: 772 | G8: 3.77M | H8: 0.0112 | J8: 45901 | K8: 9350.43 | L8: 9187.34 | M8: 9363.57 | N8: 9107.4 | O8: 15.83B | P8: 0.0178 | R8: FTSE 100 Mean Change | S8: =AVERAGE(P4:P88) -> 0.0055882353
B9: 45870 | C9: 801 | D9: 839 | E9: 875 | F9: 801 | G9: 2.44M | H9: -0.0498 | J9: 45870 | K9: 9187.34 | L9: 9132.81 | M9: 9357.51 | N9: 9027.94 | O9: 14.89B | P9: 0.006 | U9: FTSE 100 Standard Deviation, Change, % | V9: =_xlfn.STDEV.S(P4:P88) -> 0.036032427
B10: 45839 | C10: 843 | D10: 817 | E10: 867 | F10: 790 | G10: 3.07M | H10: -0.0082 | J10: 45839 | K10: 9132.81 | L10: 8760.96 | M10: 9190.73 | N10: 8726.92 | O10: 16.22B | P10: 0.0424 | R10: RNWH Median Change | S10: =MEDIAN(H4:H88) -> 0.0059 | T10: =MEDIAN(P4:P88) -> 0.0119 | U10: FTSE 100 Variance, Change, % | V10: =_xlfn.VAR.S(P4:P88) -> 0.0012983358
B11: 45809 | C11: 850 | D11: 843 | E11: 867 | F11: 787 | G11: 3.21M | H11: 0.0366 | J11: 45809 | K11: 8760.96 | L11: 8772.38 | M11: 8902.4 | N11: 8707.65 | O11: 16.09B | P11: -0.0013 | R11: RNWH Mode Change | S11: =MODE(H4:H88) -> 0.0399
B12: 45778 | C12: 820 | D12: 713 | E12: 859 | F12: 713 | G12: 3.51M | H12: 0.0861 | J12: 45778 | K12: 8772.38 | L12: 8494.85 | M12: 8824 | N12: 8468.26 | O12: 18.74B | P12: 0.0327 | AG12: Change
B13: 45748 | C13: 755 | D13: 671 | E13: 764 | F13: 604 | G13: 4.47M | H13: 0.1405 | J13: 45748 | K13: 8494.85 | L13: 8582.81 | M13: 8671.91 | N13: 7544.83 | O13: 21.43B | P13: -0.0102 | R13: Annualised Return (RNWH) | S13: =(1+S7)^12-1 -> 0.20384251
B14: 45717 | C14: 662 | D14: 657 | E14: 700 | F14: 631 | G14: 6.52M | H14: 0.0046 | J14: 45717 | K14: 8582.81 | L14: 8809.74 | M14: 8908.82 | N14: 8481.11 | O14: 20.81B | P14: -0.0258 | R14: Annualised Return (FTSE100) | S14: =(1+S8)^12-1 -> 0.069158776
B15: 45689 | C15: 659 | D15: 740 | E15: 754 | F15: 654 | G15: 4.83M | H15: -0.0997 | J15: 45689 | K15: 8809.74 | L15: 8673.96 | M15: 8820.93 | N15: 8520.2 | O15: 19.20B | P15: 0.0157 | R15: Volatolity Ratio | S15: =V6/V9 -> 2.4768855
B16: 45658 | C16: 732 | D16: 910 | E16: 941 | F16: 690 | G16: 6.54M | H16: -0.1912 | J16: 45658 | K16: 8673.96 | L16: 8173.02 | M16: 8692.84 | N16: 8160.6 | O16: 18.07B | P16: 0.0613
B17: 45627 | C17: 905 | D17: 1050 | E17: 1070 | F17: 863 | G17: 2.93M | H17: -0.1298 | J17: 45627 | K17: 8173.02 | L17: 8287.3 | M17: 8388.37 | N17: 8002.34 | O17: 14.58B | P17: -0.0138 | R17: Mean > Median (1.56% vs 0.59%) => Distribution is right-skewed (strong positive months pulling average)
B18: 45597 | C18: 1040 | D18: 1084 | E18: 1100 | F18: 1016 | G18: 3.15M | H18: -0.0494 | J18: 45597 | K18: 8287.3 | L18: 8110.1 | M18: 8307.27 | N18: 7995.87 | O18: 17.71B | P18: 0.0218 | R18: Typical monthly fluctuation ≈ ±9%
B19: 45566 | C19: 1094 | D19: 1098 | E19: 1152 | F19: 1030 | G19: 6.70M | H19: 0.0399 | J19: 45566 | K19: 8110.1 | L19: 8236.95 | M19: 8395.58 | N19: 8071.72 | O19: 18.65B | P19: -0.0154 | R19: Large extremes. High volatility
B20: 45536 | C20: 1052 | D20: 1080 | E20: 1110 | F20: 1022 | G20: 3.58M | H20: -0.0187 | J20: 45536 | K20: 8236.95 | L20: 8376.63 | M20: 8380.98 | N20: 8168.42 | O20: 16.74B | P20: -0.0167 | R20: RNWH is 2.48 times more volatile than the FTSE 100 on a monthly basis.
B21: 45505 | C21: 1072 | D21: 1098 | E21: 1104 | F21: 985 | G21: 2.67M | H21: -0.0129 | J21: 45505 | K21: 8376.63 | L21: 8283.36 | M21: 8414.37 | N21: 8008.23 | O21: 1.08B | P21: 0.001 | R21: Suggests higher idiosyncratic risk
B22: 45474 | C22: 1086 | D22: 1070 | E22: 1144 | F22: 1016 | G22: 2.79M | H22: 0.0226 | J22: 45474 | K22: 8367.98 | L22: 8164.12 | M22: 8399.88 | N22: 8056.01 | O22: 16.54B | P22: 0.025
B23: 45444 | C23: 1062 | D23: 1050 | E23: 1100 | F23: 1050 | G23: 2.66M | H23: -0.0056 | J23: 45444 | K23: 8164.12 | L23: 8275.38 | M23: 8371.72 | N23: 8112.93 | O23: 18.58B | P23: -0.0134
B24: 45413 | C24: 1068 | D24: 961.16 | E24: 1086 | F24: 935.88 | G24: 4.05M | H24: 0.1302 | J24: 45413 | K24: 8275.38 | L24: 8144.13 | M24: 8474.41 | N24: 8111.38 | O24: 21.44B | P24: 0.0161
B25: 45383 | C25: 945 | D25: 906.75 | E25: 969 | F25: 882.92 | G25: 3.95M | H25: 0.0227 | J25: 45383 | K25: 8144.13 | L25: 7952.62 | M25: 8199.95 | N25: 7793.91 | O25: 19.99B | P25: 0.0241
B26: 45352 | C26: 924 | D26: 872.32 | E26: 939 | F26: 860 | G26: 3.00M | H26: 0.056 | J26: 45352 | K26: 7952.62 | L26: 7630.02 | M26: 7975.38 | N26: 7598.47 | O26: 22.36B | P26: 0.0423 | R26: RNWH Chart
B27: 45323 | C27: 875 | D27: 900 | E27: 900 | F27: 831 | G27: 2.91M | H27: -0.0057 | J27: 45323 | K27: 7630.02 | L27: 7630.57 | M27: 7748.73 | N27: 7492.98 | O27: 21.73B | P27: -0.0001
B28: 45292 | C28: 880 | D28: 840 | E28: 884 | F28: 804 | G28: 3.63M | H28: 0.0244 | J28: 45292 | K28: 7630.57 | L28: 7733.24 | M28: 7764.37 | N28: 7404.08 | O28: 17.95B | P28: -0.0133
B29: 45261 | C29: 859 | D29: 818 | E29: 867 | F29: 800 | G29: 2.57M | H29: 0.0202 | J29: 45261 | K29: 7733.24 | L29: 7453.75 | M29: 7762.88 | N29: 7453.75 | O29: 14.84B | P29: 0.0375
B30: 45231 | C30: 842 | D30: 714.16 | E30: 842 | F30: 705 | G30: 3.22M | H30: 0.1743 | J30: 45231 | K30: 7453.75 | L30: 7321.72 | M30: 7533.77 | N30: 7304.89 | O30: 15.17B | P30: 0.018
B31: 45200 | C31: 717 | D31: 723 | E31: 740 | F31: 672 | G31: 2.51M | H31: 0.0056 | J31: 45200 | K31: 7321.72 | L31: 7608.08 | M31: 7687.91 | N31: 7279.86 | O31: 15.12B | P31: -0.0376
B32: 45170 | C32: 713 | D32: 726 | E32: 739 | F32: 699 | G32: 2.89M | H32: -0.007 | J32: 45170 | K32: 7608.08 | L32: 7439.13 | M32: 7746.53 | N32: 7369.64 | O32: 14.47B | P32: 0.0227
B33: 45139 | C33: 718 | D33: 741.4 | E33: 774 | F33: 700 | G33: 6.97M | H33: -0.0164 | J33: 45139 | K33: 7439.13 | L33: 7699.41 | M33: 7715.24 | N33: 7215.76 | O33: 15.22B | P33: -0.0338
B34: 45108 | C34: 730 | D34: 744.88 | E34: 766 | F34: 711 | G34: 3.40M | H34: -0.0188 | J34: 45108 | K34: 7699.41 | L34: 7531.53 | M34: 7722.92 | N34: 7229.57 | O34: 12.96B | P34: 0.0223
B35: 45078 | C35: 744 | D35: 727 | E35: 762 | F35: 704 | G35: 3.35M | H35: 0.0406 | J35: 45078 | K35: 7531.53 | L35: 7446.14 | M35: 7687.61 | N35: 7401.18 | O35: 15.99B | P35: 0.0115 | AG35: Change
B36: 45047 | C36: 715 | D36: 712 | E36: 758.68 | F36: 707 | G36: 3.96M | H36: -0.0165 | J36: 45047 | K36: 7446.14 | L36: 7870.57 | M36: 7898.69 | N36: 7446.14 | O36: 17.58B | P36: -0.0539
B37: 45017 | C37: 727 | D37: 674.35 | E37: 734 | F37: 650 | G37: 2.66M | H37: 0.0754 | J37: 45017 | K37: 7870.57 | L37: 7631.74 | M37: 7936.11 | N37: 7631.74 | O37: 13.30B | P37: 0.0313
B38: 44986 | C38: 676 | D38: 713 | E38: 713 | F38: 660.17 | G38: 2.71M | H38: -0.0519 | J38: 44986 | K38: 7631.74 | L38: 7876.28 | M38: 7974.4 | N38: 7206.82 | O38: 22.22B | P38: -0.031
B39: 44958 | C39: 713 | D39: 742 | E39: 760 | F39: 683.1 | G39: 1.27M | H39: -0.026 | J39: 44958 | K39: 7876.28 | L39: 7771.7 | M39: 8047.06 | N39: 7745.43 | O39: 16.62B | P39: 0.0135
B40: 44927 | C40: 732 | D40: 731.98 | E40: 760 | F40: 701 | G40: 1.93M | H40: 0 | J40: 44927 | K40: 7771.7 | L40: 7451.74 | M40: 7875.58 | N40: 7448.69 | O40: 17.09B | P40: 0.0429
...

Sheet CPI 
A1: Main
B2: Inflation (CPI) m/m
B3: Release date | C3: Actual
B4: 18/02/2026 (Jan) | C4: 0.004 | D4: forecast
B5: 21/01/2026 (Dec) | C5: 0.004
B6: 17/12/2025 (Nov) | C6: -0.002
B7: 19/11/2025 (Oct) | C7: 0.004
B8: 22/10/2025 (Sep) | C8: 0
B9: 17/09/2025 (Aug) | C9: 0.003
B10: 20/08/2025 (Jul) | C10: 0.001
B11: 16/07/2025 (Jun) | C11: 0.003
B12: 18/06/2025 (May) | C12: 0.002
B13: 21/05/2025 (Apr) | C13: 0.012
B14: 16/04/2025 (Mar) | C14: 0.003
B15: 26/03/2025 (Feb) | C15: 0.004
B16: 19/02/2025 (Jan) | C16: -0.001
... B88: 13/02/2019 (Jan) | C88: -0.008

Sheet Interest Rate
A1: Main
B2: Bank Rate history and data | Bank of England Database
B3: Date Changed | C3: Rate
B4: 18 Dec 25 | C4: 3.75
B5: 07 Aug 25 | C5: 4
B6: 08 May 25 | C6: 4.25
B7: 06 Feb 25 | C7: 4.5
B8: 07 Nov 24 | C8: 4.75
B9: 01 Aug 24 | C9: 5
B10: 03 Aug 23 | C10: 5.25
B11: 22 Jun 23 | C11: 5
B12: 11 May 23 | C12: 4.5
B13: 23 Mar 23 | C13: 4.25
B14: 02 Feb 23 | C14: 4
B15: 15 Dec 22 | C15: 3.5
... B261: 20 Jan 75 | C261: 11.25
